Workbook

Sheet TOC
A1: File | B1: Translator | C1: Status | D1: Note
A2: AccessoryItemMessage.csv | C2: =SUMPRODUCT(--(LEN(AccessoryItemMessage!C2:C247)>1))/SUMPRODUCT(--(LEN(AccessoryItemMessage!B2:B247)>1)) | D2: Thảo luận tại forum: https://viethoagame.com/threads/i-am-setsuna.90/ Hoặc discord #set: https://discord.gg/YE59VVK
A3: AutoSetsunaSystemDataMessage.csv | C3: =SUMPRODUCT(--(LEN(AutoSetsunaSystemDataMessage!C2:C21)>1))/SUMPRODUCT(--(LEN(AutoSetsunaSystemDataMessage!B2:B21)>1))
A4: BraveStoryCategoryMessage.csv | C4: =SUMPRODUCT(--(LEN(BraveStoryCategoryMessage!C2:C120)>1))/SUMPRODUCT(--(LEN(BraveStoryCategoryMessage!B2:B120)>1))
A5: BraveStoryCoopMessage.csv | C5: =SUMPRODUCT(--(LEN(BraveStoryCoopMessage!C2:C138)>1))/SUMPRODUCT(--(LEN(BraveStoryCoopMessage!B2:B138)>1))
A6: BraveStoryGeographyMessage.csv | C6: =SUMPRODUCT(--(LEN(BraveStoryGeographyMessage!C2:C185)>1))/SUMPRODUCT(--(LEN(BraveStoryGeographyMessage!B2:B185)>1))
A7: BraveStoryItemMessage.csv | C7: =SUMPRODUCT(--(LEN(BraveStoryItemMessage!C2:C356)>1))/SUMPRODUCT(--(LEN(BraveStoryItemMessage!B2:B356)>1))
A8: BraveStoryMateriaMessage.csv | C8: =SUMPRODUCT(--(LEN(BraveStoryMateriaMessage!C2:C223)>1))/SUMPRODUCT(--(LEN(BraveStoryMateriaMessage!B2:B223)>1))
A9: BraveStoryMemoMessage.csv | C9: =SUMPRODUCT(--(LEN(BraveStoryMemoMessage!C2:C77)>1))/SUMPRODUCT(--(LEN(BraveStoryMemoMessage!B2:B77)>1))
A10: BraveStoryMonsterMessage.csv | C10: =SUMPRODUCT(--(LEN(BraveStoryMonsterMessage!C2:C207)>1))/SUMPRODUCT(--(LEN(BraveStoryMonsterMessage!B2:B207)>1))
A11: BraveStoryNoteMessage.csv | C11: =SUMPRODUCT(--(LEN(BraveStoryNoteMessage!C2:C75)>1))/SUMPRODUCT(--(LEN(BraveStoryNoteMessage!B2:B75)>1))
A12: BraveStoryPersonMessage.csv | C12: =SUMPRODUCT(--(LEN(BraveStoryPersonMessage!C2:C101)>1))/SUMPRODUCT(--(LEN(BraveStoryPersonMessage!B2:B101)>1))
A13: BraveStorySetsunaMessage.csv | C13: =SUMPRODUCT(--(LEN(BraveStorySetsunaMessage!C2:C36)>1))/SUMPRODUCT(--(LEN(BraveStorySetsunaMessage!B2:B36)>1))
A14: BraveStorySublimationMessage.csv | C14: =SUMPRODUCT(--(LEN(BraveStorySublimationMessage!C2:C24)>1))/SUMPRODUCT(--(LEN(BraveStorySublimationMessage!B2:B24)>1))
A15: BraveStoryWeaponMessage.csv | C15: =SUMPRODUCT(--(LEN(BraveStoryWeaponMessage!C2:C84)>1))/SUMPRODUCT(--(LEN(BraveStoryWeaponMessage!B2:B84)>1))
A16: ConsumptionItemMessage.csv | C16: =SUMPRODUCT(--(LEN(ConsumptionItemMessage!C2:C37)>1))/SUMPRODUCT(--(LEN(ConsumptionItemMessage!B2:B37)>1))
A17: CookingItemMessage.csv | C17: =SUMPRODUCT(--(LEN(CookingItemMessage!C2:C45)>1))/SUMPRODUCT(--(LEN(CookingItemMessage!B2:B45)>1))
A18: EnemyBossSkillDataMessage.csv | C18: =SUMPRODUCT(--(LEN(EnemyBossSkillDataMessage!C2:C549)>1))/SUMPRODUCT(--(LEN(EnemyBossSkillDataMessage!B2:B549)>1))
A19: EnemyCoopSkillDataMessage.csv | C19: =SUMPRODUCT(--(LEN(EnemyCoopSkillDataMessage!C2:C81)>1))/SUMPRODUCT(--(LEN(EnemyCoopSkillDataMessage!B2:B81)>1))
A20: EnemySetParameterMessage.csv | C20: =SUMPRODUCT(--(LEN(EnemySetParameterMessage!C2:C209)>1))/SUMPRODUCT(--(LEN(EnemySetParameterMessage!B2:B209)>1))
A21: EnemySkillDataMessage.csv | C21: =SUMPRODUCT(--(LEN(EnemySkillDataMessage!C2:C181)>1))/SUMPRODUCT(--(LEN(EnemySkillDataMessage!B2:B181)>1))
A22: EventItemMessage.csv | C22: =SUMPRODUCT(--(LEN(EventItemMessage!C2:C65)>1))/SUMPRODUCT(--(LEN(EventItemMessage!B2:B65)>1))
A23: GrimreaperSkillDataMessage.csv | C23: =SUMPRODUCT(--(LEN(GrimreaperSkillDataMessage!C2:C39)>1))/SUMPRODUCT(--(LEN(GrimreaperSkillDataMessage!B2:B39)>1))
A24: IntensifyMessage.csv | C24: =SUMPRODUCT(--(LEN(IntensifyMessage!C2:C13)>1))/SUMPRODUCT(--(LEN(IntensifyMessage!B2:B13)>1))
A25: ItemSkillDataMessage.csv | C25: =SUMPRODUCT(--(LEN(ItemSkillDataMessage!C2:C11)>1))/SUMPRODUCT(--(LEN(ItemSkillDataMessage!B2:B11)>1))
A26: KishilSkillDataMessage.csv | C26: =SUMPRODUCT(--(LEN(KishilSkillDataMessage!C2:C39)>1))/SUMPRODUCT(--(LEN(KishilSkillDataMessage!B2:B39)>1))
A27: MaterialItemMessage.csv | C27: =SUMPRODUCT(--(LEN(MaterialItemMessage!C2:C819)>1))/SUMPRODUCT(--(LEN(MaterialItemMessage!B2:B819)>1))
A28: MateriaMessage.csv | C28: =SUMPRODUCT(--(LEN(MateriaMessage!C2:C877)>1))/SUMPRODUCT(--(LEN(MateriaMessage!B2:B877)>1))
A29: NPCSetParameterMessage.csv | C29: =SUMPRODUCT(--(LEN(NPCSetParameterMessage!C2:C667)>1))/SUMPRODUCT(--(LEN(NPCSetParameterMessage!B2:B667)>1))
A30: PlayerSetParameterMessage.csv | C30: =SUMPRODUCT(--(LEN(PlayerSetParameterMessage!C2:C19)>1))/SUMPRODUCT(--(LEN(PlayerSetParameterMessage!B2:B19)>1))
A31: PlayerSkillDataMessage.csv | C31: =SUMPRODUCT(--(LEN(PlayerSkillDataMessage!C2:C39)>1))/SUMPRODUCT(--(LEN(PlayerSkillDataMessage!B2:B39)>1))
A32: ScenarioMessageData_Chapter_1.csv | C32: =SUMPRODUCT(--(LEN(ScenarioMessageData_Chapter_1!C2:C1405)>1))/SUMPRODUCT(--(LEN(ScenarioMessageData_Chapter_1!B2:B1405)>1))
A33: ScenarioMessageData_Chapter_2.csv | C33: =SUMPRODUCT(--(LEN(ScenarioMessageData_Chapter_2!C2:C1715)>1))/SUMPRODUCT(--(LEN(ScenarioMessageData_Chapter_2!B2:B1715)>1))
A34: ScenarioMessageData_Chapter_3.csv | C34: =SUMPRODUCT(--(LEN(ScenarioMessageData_Chapter_3!C2:C1346)>1))/SUMPRODUCT(--(LEN(ScenarioMessageData_Chapter_3!B2:B1346)>1))
A35: ScenarioMessageData_Chapter_4.csv | C35: =SUMPRODUCT(--(LEN(ScenarioMessageData_Chapter_4!C2:C807)>1))/SUMPRODUCT(--(LEN(ScenarioMessageData_Chapter_4!B2:B807)>1))
A36: ScenarioMessageData_NormalConversation.csv | C36: =SUMPRODUCT(--(LEN(ScenarioMessageData_NormalConv!C2:C3)>1))/SUMPRODUCT(--(LEN(ScenarioMessageData_NormalConv!B2:B3)>1))
A37: SetsunaSkillDataMessage.csv | C37: =SUMPRODUCT(--(LEN(SetsunaSkillDataMessage!C2:C39)>1))/SUMPRODUCT(--(LEN(SetsunaSkillDataMessage!B2:B39)>1))
A38: SetsunaSystemDataMessage.csv | C38: =SUMPRODUCT(--(LEN(SetsunaSystemDataMessage!C2:C493)>1))/SUMPRODUCT(--(LEN(SetsunaSystemDataMessage!B2:B493)>1))
A39: SionSkillDataMessage.csv | C39: =SUMPRODUCT(--(LEN(SionSkillDataMessage!C2:C39)>1))/SUMPRODUCT(--(LEN(SionSkillDataMessage!B2:B39)>1))
A40: SublimationDataMessage.csv | C40: =SUMPRODUCT(--(LEN(SublimationDataMessage!C2:C45)>1))/SUMPRODUCT(--(LEN(SublimationDataMessage!B2:B45)>1))
...

Sheet AccessoryItemMessage
A1: ID | B1: English | C1: Vietnamese | D1: Note
A2: 0.001_ | B2: 2 | D2: 2
A3: 1_ | B3: True | D3: True
A4: 1.001_ | B4: 0 | D4: 0
A5: 2_ | B5: 121 | D5: 121
A6: 3_ | B6: Mark of the Masked Tribe | C6: Dấu hiệu của bộ tộc Mặt Nạ | D6: 仮面族の証
A7: 4_ | B7: A mark carried by adult members of the masked tribe. It is given to them by the chieftain to signify their coming of age. | C7: Là dấu hiệu ở người trưởng thành của bộ tộc Mặt nạ. Họ được mang dấu hiệu này sau lễ trưởng thành, được cấp bởi tộc trưởng. | D7: 成人した仮面の一族が持つ証。 族長に一人前と認められた時に渡される法器。
A8: 5_ | B8: Dawn Amulet | C8: Bùa Bình Minh | D8: 暁の守り
A9: 6_ | B9: This amulet is adorned with a rising sun motif. It is imbued with a magic spell that has been passed down in the village for many years. | C9: Một tấm mề đay khắc hình mặt trời mọc. Được ếm 1 câu thần chú được truyền lại trong làng từ rất lâu. | D9: 太陽が昇る意匠がほどこされたお守り。 集落に伝わるまじないが込められている。
A10: 7_ | B10: Frog Doll | C10: Búp Bê Ếch | D10: カエルの人形
A11: 8_ | B11: A doll depicting a mysterious creature with green skin and bulging eyes. Some say it is a proto- creature that conquered land and sea long ago. | C11: Một con búp bê có hình dáng 1 sinh vật kì quái với làn da xanh và mắt trố. Nó được cho là 1 sinh vật cổ đại từng thống trị thế giới. | D11: 表面が緑色で目が大きい謎の生き物を象った人形。 一説によると古代、海と陸を制覇した 生物の原型とも言われているが定かではない。
A12: 9_ | B12: Ancient Charm | C12: Trang Sức Cổ Đại | D12: オールドチャーム
A13: 10_ | B13: A metal charm fashioned in the shape of a wing. It is old and worn, but carefully maintained, and it is clear that its former owner took great care of it. | C13: Một đồ trang sức có hình đôi cánh. Dù cũ và sắp hỏng nhưng nó được bảo quản cẩn thận. Rõ ràng chủ trước rất trân trọng món đồ này. | D13: 羽の形をした金属製の装飾品。 古ぼけてはいるが、手入れが行き届いており 前の持ち主が大事にしていたことがわかる。
A14: 11_ | B14: Firestone | C14: Đá Lửa | D14: ファイアストーン
A15: 12_ | B15: When held to the light, the fissures inside this stone resemble flickering flames. | C15: Dưới ánh sáng, họa tiết bên trong viên đá có hình ngọn lửa. | D15: 見る角度によって 内部の亀裂が炎のゆらぎにもみえる紅玉。
A16: 13_ | B16: Ancient Crest | C16: Huy Hiệu Cổ Đại | D16: 古の紋章
A17: 14_ | B17: This pendant bears the crest of an ancient royal family that fell long ago. | C17: Chiếc huân chương có khắc huy hiệu của 1 Hoàng tộc cổ đại. | D17: 今はなき、古代王家の紋章が刻まれたペンダント。
... A247: 244_ | B247: This talisman is said to grant happiness to its bearer. It becomes more powerful with each successive owner, granting even greater happiness. | C247: Phù chú này sẽ mang đến hạnh phúc cho người dùng. Nó trở nên mạnh hơn khi ở trong tay người giàu, mang lại nhiều hạnh phúc hơn/ | D247: 持つ物に幸せを与えるとされている法器。 さまざまな人に受け継がれてきた想いが 持ち主に更なる幸福をもたらす。

Sheet AutoSetsunaSystemDataMessage
A1: ID | B1: English | C1: Vietnamese | D1: Note
A2: 244.001_ | B2: 2 | D2: 2
A3: 245_ | B3: True | D3: True
A4: 245.001_ | B4: 0 | D4: 0
A5: 245.002_ | B5: 8 | D5: 8
A6: 246_ | B6: Chrono Burst | C6: Bùng Nổ | D6: クロノバースト
A7: 247_ | B7: ATB speed is greatly increased. However, combos can no longer be used. | C7: Tốc độ hồi ATB tăng mạnh. Tuy nhiên, không thể dùng combo được nữa. | D7: ATBが高速でたまり、連続行動ができる。 その代わり、連携が使えなくなる。
A8: 248_ | B8: Momentum Control | C8: Điều Khiển Momentum | D8: 刹那の極意
A9: 249_ | B9: SP speed is greatly increased. The power of Momentum mode effects is also increased. | C9: Tốc độ hồi SP tăng mạnh. Hiệu quả khi sử dụng chế độ Momentum tăng. | D9: SPがたまりやすくなる。 刹那システムの発動効果も強くなる。
A10: 250_ | B10: Elemental Inflation | C10: Điều Khiển Nguyên Tố | D10: 属性インフレ
A11: 251_ | B11: All attacks cause all-elemental damage, and all resistances match the highest resistance. | C11: Đòn tấn công chứa đựng tấn cả thuộc tính, khả năng kháng được đẩy toàn bộ bằng khả năng kháng cao nhất. | D11: 攻撃属性が強制的に全属性になる。 耐性も全ての耐性が一番高い数値になる。
A12: 252_ | B12: Probability Change | C12: Thay Đổi Xác Suất | D12: 確率変動
A13: 253_ | B13: Critical hits are generated more easily, and status ailments are inflicted more easily. | C13: Tăng khả năng tung đòn chí mạng, đồng thời tăng khả năng gây ra hiệu ứng. | D13: クリティカルが発生しやすくなる。 状態異常も発生しやすくなる。
A14: 254_ | B14: Timelight | C14: Ánh Sáng Thời Gian | D14: 創刻の光
A15: 255_ | B15: Damage adjustment counters will no longer be reset, even by enemy attacks. | C15: Sát thương gây ra sẽ không bị ảnh hưởng. | D15: 特殊な威力補正用カウントがリセットしない。 敵の行動によるリセットも起きなくなる。
A16: 256_ | B16: Guardian Goddess | C16: Kẻ Bảo Vệ Nữ Thần | D16: 聖女の加護
A17: 257_ | B17: HP of allies will no longer be reduced below 1, except due to Death. | C17: Lượng HP của đồng minh không bao giờ xuống dưới 1, kể cả bị Thần Chết tấn công. | D17: 味方のHPが1以下にならなくなる。 ただし、即死で戦闘不能になることはある。
... A21: 261_ | B21: Fluxation occurs more easily, and tech power rises based on no. of Fluxes. | C21: Sự đột biến năng lượng xảy ra thường xuyên, sát thương chiêu thức tăng. | D21: 昇華が発生しやすくなる。 魔法の昇華数が多いほど、威力が強くなる。

Sheet BraveStoryCategoryMessage
A1: ID | B1: English | C1: Vietnamese | D1: Note
A2: 261.001_ | B2: 2 | D2: 2
A3: 262_ | B3: True | D3: True
A4: 262.001_ | B4: 0 | D4: 0
A5: 263_ | B5: 115 | D5: 115
A6: 264_ | B6: Nive Island | C6: Đảo Nive | D6: モル島
A7: 265_ | B7: Floneian Territories | C7: Lãnh thổ người Floneian | D7: ウカテイナ領
A8: 266_ | B8: Northern Frontier | C8: Biên giới phía Bắc | D8: 北方辺境
A9: 267_ | B9: Fridging Mountain Range | C9: Dãy Băng Sơn | D9: オッカオッカ山岳地帯
A10: 268_ | B10: Remote Islands | C10: Hòn đảo hẻo lánh | D10: 絶海群島
A11: 269_ | B11: F Area | C11: Khu vực F | D11: F地方
A12: 270_ | B12: G Area | C12: Khu vực G | D12: G地方
A13: 271_ | B13: H Area | C13: Khu vực H | D13: H地方
A14: 272_ | B14: I Area | C14: Khu vực I | D14: I地方
A15: 273_ | B15: J Area | C15: Khu vực J | D15: J地方
A16: 274_ | B16: Items | C16: Vật Phẩm | D16: 道具
A17: 275_ | B17: Tempering Items | C17: Vật Phẩm Tạm Thời | D17: 武器強化道具
... A120: 378_ | B120: Extra | C120: Thêm | D120: 番外

Sheet BraveStoryCoopMessage
A1: ID | B1: English | C1: Vietnamese | D1: Note
A2: 378.001_ | B2: 2 | D2: 2
A3: 379_ | B3: True | D3: True
A4: 379.001_ | B4: 0 | D4: 0
A5: 380_ | B5: 133 | D5: 133
A6: 381_ | B6: Synchronizes the healing power of the users, recovering the HP of all allies and healing all status ailments. When used in Momentum mode, it will also recover MP. | C6: Đồng bộ hóa sức mạnh chữa bệnh của người dùng, phục hồi HP của tất cả các đồng minh và chữa lành tất cả các trạng thái bệnh. Khi được sử dụng ở chế độ Momentum, nó cũng sẽ phục hồi MP. | D6: 癒しの魔力を同調させて、HP回復と全ての状態異常を解除する効果が全体に発生する。 刹那システムを発動すると、MP回復することもできる。
A7: 382_ | B7: One user imbues the other's sword with the power of lightning, producing a powerful strike. Causes increased damage when striking a foe's weakness. When used in Momentum mode, damage will be even further increased when striking a weakness. | C7: "Một người sử dụng thấm nhuần thanh kiếm của người kia với sức mạnh của tia sét, tạo ra một đòn tấn công mạnh mẽ. Gây sát thương tăng lên khi tấn công điểm yếu của kẻ thù. | D7: 雷の力を剣にのせて、叩きつける攻撃である。弱点属性に攻撃したときに威力が大きくなるという特性がある。 刹那システムを発動すると、弱点属性を攻撃したときに威力が大きくなる攻撃がさらに発生する。
A8: 383_ | B8: This combo can only be used by two people with an unshakable bond. It creates harmony among the party, raising the stats of all allies to the same value as that of the ally with the highest stat. When used in Momentum mode, its duration will be increased. | C8: Khi sử dụng ở chế độ Momentum, sát thương sẽ còn tăng hơn nữa khi chạm vào một điểm yếu. " | D8: 揺るぎのない深いつながりがあるからこそできる連携であり、パーティの波長を同調させることで、全員の能力値がパーティの中で一番高い数値になる。 刹那システムを発動すると、発生時間が長くなる。
A9: 384_ | B9: The users' strikes cross each other, creating an X-shaped trail that causes damage to enemies. It inflicts more damage the sooner the two strikes cross. When used in Momentum mode, this combo will also cause additional physical damage to a single enemy. | C9: Đòn đánh của hai người dùng giao nhau, tạo thành vệt chém hình chữ X gây sát thương lên kẻ địch. Càng tung đòn giao kiếm sớm sát thương càng cao. Khi sử dụng ở chế độ Xung Lực, liên chiêu này sẽ gây thêm sát thương vật lý phụ lên một mục tiêu. | D9: エックスの軌跡ができるように2人で交差するように斬り抜ける連携である。斬撃の交差点が近いほど威力が大きくなる。 刹那システムを発動すると、敵単体に物理攻撃が発生する。
A10: 385_ | B10: This combo uses the combined magical energy of the two users to manipulate space-time, causing effects to be generated twice when Momentum mode is triggered. When used in Momentum mode, its duration will be increased. | C10: Liên chiêu này kết hợp ma lực của hai người dùng để thao túng không-thời gian, giúp kích hoạt hiệu ứng hai lần khi ở chế độ Xung Lực. Khi sử dụng ở chế độ Xung Lực, thời gian hiệu lực của kỹ năng sẽ được gia tăng. | D10: 2人で集束した膨大な魔力によって時空を操作する連携である。刹那システムを発動したときに連続して同じ効果が発生するようになる。 刹那システムを発動すると、発生時間が長くなる。
A11: 386_ | B11: This combo uses Momentum power to create a barrier, then destroys it, triggering a blast that causes damage to enemies. It also raises the SP gauges of all allies. When used in Momentum mode, it will also cause physical damage that increases in power according to how high SP is. | C11: Liên chiêu này sử dụng sức mạnh Xung Lực tạo ra lá chắn rồi phá hủy nó, giải phóng vụ nổ gây sát thương lên kẻ địch. Đồng thời làm tăng thanh SP của toàn đội. Khi dùng ở chế độ Xung Lực, nó sẽ gây thêm sát thương vật lý tăng theo lượng SP. | D11: 刹那の力によって発生した結界を破壊した衝撃で攻撃する。攻撃するだけでなく、味方のSPもたまるという汎用性の高い連携である。 刹那システムを発動すると、SPが高いほど威力が大きくなる物理攻撃が発生する。
A12: 387_ | B12: Energy blades fired by the two users create a cross-shaped slash. When used in Momentum mode, this combo will also cause additional physical damage to all enemies. | C12: Lưỡi kiếm năng lượng được phóng ra bởi hai người dùng tạo thành một nhát chém chữ thập hình dấu X. Khi sử dụng ở chế độ Xung Lực, liên chiêu này sẽ gây thêm sát thương vật lý phụ lên toàn bộ kẻ địch. | D12: 闘気の刃で生みだす十字斬りが発生する。 刹那システムを発動すると、敵全体に物理攻撃が発生する。
A13: 388_ | B13: Hits all enemies with a powerful pressure attack that can sometimes also inflict Paralysis, Confusion, and Stun. When used in Momentum mode, this combo will also reduce Attack and Defense. | C13: Tấn công toàn bộ kẻ địch bằng áp lực kiếm khí cực mạnh, có tỉ lệ gây trạng thái Tê Liệt, Hỗn Loạn và Choáng. Khi sử dụng ở chế độ Xung Lực, liên chiêu này cũng sẽ làm giảm chỉ số Tấn Công và Phòng Thủ của địch. | D13: 敵を威圧して攻撃しながら、麻痺と混乱とスタンを発生させる。 刹那システムを発動すると、さらに攻撃力と防御力も低下させる攻撃が発生する。
A14: 389_ | B14: Launches enemies into the air before sending them hurtling down again. Has a high critical hit rate, and also ignores 30% of Defense. When used in Momentum mode, this combo will also boost evasion rate, making it effective in terms of both attack and defense. | C14: Hất tung kẻ địch lên không trung trước khi giáng mạnh chúng xuống đất. Đòn đánh có tỉ lệ chí mạng cao và bỏ qua 30% Phòng Thủ. Khi sử dụng ở chế độ Xung Lực, liên chiêu này sẽ tăng tỉ lệ né tránh, hiệu quả trong cả tấn công lẫn phòng ngự. | D14: 敵を打ち上げて叩き落とす攻撃である。クリティカル率が高く、防御を30%を無視する特性がある。 刹那システムを発動すれば、回避率が上昇するため、攻防一体の連携となる。
A15: 390_ | B15: Charges the blade with absorptive magical energy and slashes at surrounding foes. 40% of the damage inflicted is absorbed by all allies as HP. When used in Momentum mode, HP will also be recovered. An excellent combo that combines both attack and recovery. | C15: Truyền ma lực hấp thụ vào lưỡi kiếm và chém quét mọi kẻ thù xung quanh. 40% lượng sát thương gây ra được toàn đội hấp thụ thành HP. Khi sử dụng ở chế độ Xung Lực, lượng HP hồi phục sẽ được gia tăng, tạo nên đòn đánh hoàn hảo cả công lẫn thủ. | D15: 吸収の魔力を剣にこめて、周囲を斬りつける攻撃である。与えたダメージの40%を味方全体でHP吸収する。 刹那システムを発動すると、HPを回復することもできる。攻撃以上に回復として優秀な連携である。
A16: 391_ | B16: One user imbues the other's sword with the power of fire, producing a powerful strike. Causes increased damage when striking a foe's weakness. When used in Momentum mode, damage will be even further increased when striking a weakness. | C16: Một người truyền hỏa lực vào kiếm của người kia,|giáng đòn công kích dũng mãnh. Gây thêm sát thương|khi đánh trúng điểm yếu của kẻ địch. Khi dùng ở chế độ|Momentum, sát thương trúng điểm yếu sẽ tăng mạnh hơn|nữa. | D16: 炎の力を剣にのせて、叩きつける攻撃である。弱点属性に攻撃したときに威力が大きくなるという特性がある。 刹那システムを発動すると、弱点属性を攻撃したときに威力が大きくなる攻撃がさらに発生する。
A17: 392_ | B17: Attacks by summoning a meteor storm from the skies above, causing damage that ignores 50% of Defense. When used in Momentum mode, this combo will also cause additional magical damage to a single enemy. The single-user tech "Meteo" was originally adapted from this combo. | C17: Tấn công bằng cách triệu hồi một cơn bão thiên thạch từ bầu trời, gây sát thương bỏ qua 50% Phòng Thủ. Khi sử dụng ở chế độ Xung Lực, chiêu thức gây thêm sát thương ma thuật phụ lên một kẻ địch. Kỹ năng đơn lẻ 'Thiên Thạch' vốn được phỏng theo liên chiêu này. | D17: 天から膨大な流星が降り注ぐ攻撃である。防御を50%無視する効果がある。 刹那システムを発動すると、魔法攻撃が敵単体に発生する。 連携として編み出されたメテオの本来の形であり、後に1人でも使えるようにしたのが現在のメテオである。
... A138: 513_ | B138: This combo is a variation of Omega Drive, and its appearance is the same. It is less powerful, but when used in Momentum mode will cause additional special damage to all enemies that becomes more powerful according to the number of status boosts in effect. | C138: This combo is a variation of Omega Drive, and its appearance is the same. It is less powerful, but when used in Momentum mode will cause additional special damage lên toàn bộ kẻ địch that becomes more powerful according to the number of status boosts in effect. | D138: オメガドライブの特異版であり、見た目は同じである。 威力は控えめだが、刹那システムを発動すると、発生中の状態強化数が多いほど威力が大きくなる特殊攻撃が敵全体に発生する。

Sheet BraveStoryItemMessage
A1: ID | B1: English | C1: Vietnamese | D1: Note
A2: 561.001_ | B2: 2 | D2: 2
A3: 562_ | B3: True | D3: True
A4: 562.001_ | B4: 0 | D4: 0
A5: 563_ | B5: 351 | D5: 351
A6: 564_ | B6: Potion | C6: Thuốc Hồi Máu | D6: ポーション
A7: 565_ | B7: Mid-Potion | C7: Thuốc Hồi Máu - Trung | D7: ミドルポーション
A8: 566_ | B8: Hi-Potion | C8: Thuốc Hồi Máu - Cao | D8: ハイポーション
A9: 567_ | B9: Ether | C9: Thuốc Hồi MP | D9: エーテル
A10: 568_ | B10: Mid-Ether | C10: Thuốc Hồi MP - Trung | D10: ミドルエーテル
A11: 569_ | B11: Hi-Ether | C11: Thuốc Hồi MP - Cao | D11: ハイエーテル
A12: 570_ | B12: Elixir | C12: Elixir | D12: エリクサー
A13: 571_ | B13: Megalixir | C13: WOW Elixir | D13: ラストエリクサー
A14: 572_ | B14: Antidote | C14: Thuốc Giải Độc | D14: 毒消し
A15: 573_ | B15: Crescent Grass | C15: Cỏ Mặt Trăng | D15: 三日月草
A16: 574_ | B16: Smelling Salts | C16: Muối Bốc Mùi | D16: 気付け薬
A17: 575_ | B17: Panacea | C17: Panacea | D17: 万能薬
... A356: 914_ | B356: Lost Wallet | C356: Cái Ví Bị Thất Lạc | D356: だれかのさいふ

Sheet BraveStoryMateriaMessage
A1: ID | B1: English | C1: Vietnamese | D1: Note
A2: 914.001_ | B2: 2 | D2: 2
A3: 915_ | B3: True | D3: True
A4: 915.001_ | B4: 0 | D4: 0
A5: 916_ | B5: 218 | D5: 218
A6: 917_ | B6: The user channels magical energy into the blade, then swings it around, sending foes flying. Offers a wide attack range, and is also able to knock back enemies. When used in Momentum mode, it will also cause additional physical damage to all enemies. The channeling of magical energy is not hard to pull off, making it a simple and useful tech that is a favorite among those who make their living as mercenaries. | C6: Người dùng truyền năng lượng vào lưỡi kiếm rồi vung kiếm, hất tung kẻ địch. Là chiêu thức tấn công diện rộng, đồng thời có khả năng làm ngã choáng kẻ địch. Khi sử dụng chiêu ở chế độ Momentum sẽ gây thêm sát thương đối với toàn bộ kẻ địch. Việc truyền năng lượng có thể dễ dàng dừng lại, khiến cho chiêu thức trở nên đơn giản và hữu dụng, là chiêu thức yêu thích của lính đánh thuê. | D6: 魔力を剣に込めて、回転しながら斬り払う攻撃である。広い範囲に攻撃ができる上に、敵を吹っ飛ばすこともできる。刹那システムを発動すると、敵全体に物理攻撃が発生する。 魔力運用も難しいわけではなく、扱いやすい上に利便性も高く、傭兵稼業を生業にする者たちに愛用されている。
A7: 918_ | B7: Uses healing energy to aid the body's recovery from damage. As well as recovering HP, the ATB gauge will already be partially full after use, allowing another action to be performed in quick succession. When used in Momentum mode, it will also heal any status ailments, making it a popular tech among those who often fight alone. | C7: Sử dụng năng lực trị thương tự điều trị cho bản thân. Ngoài việc hồi phục HP, thanh ATB cũng sẽ đầy 1 phần sau khi sử dụng, cho phép người chơi thực hiện hành động khác nhanh chóng. Khi dùng ở chế độ Momentum, mọi hiệu ứng bất lợi bị giải trừ, đây là một chiêu thức phổ biến với người chơi đơn lẻ. | D7: 癒しの魔力をもって、身体の再生を促す魔法である。HPを回復することができるわけだが、使用後にATBがたまっている状態になるので、すぐに他の行動に移れるという利点がある。 刹那システムを発動すると、発生している状態異常を解除することができるため、一人で戦う機会が多い人から評価が高い。
A8: 919_ | B8: Releases a blast of magical energy next to the enemy. Out of the many magical attacks available, this is one of the few non-elemental ones, making it very valuable. When used in Momentum mode, it will also cause additional magical damage to a single enemy. Although a simple tech, its uses are wide-ranging, and its ease of use makes it one that is definitely worth learning. | C8: Giải phóng một vụ nổ pháp thuật ở gần kẻ địch. Trong số rất nhiều phép thuật tấn công, đây là một trong số ít những phép thuật phi nguyên tố, điều khiến nó trở nên giá trị. Khi dùng ở chế độ Momentum, nó sẽ gây thêm sát thương cho 1 kẻ địch. Dù đơn giản, chiêu thức này có cách sử dụng rất đa dạng và dễ sử dụng, là một chiêu thức đáng học. | D8: 圧縮した魔力を敵の懐で解放して、暴発させて攻撃する。魔法攻撃はたくさんあるが、無属性のものは少ないために、貴重な攻撃である。刹那システムを発動すると、敵単体に魔法攻撃が発生する。 単純な攻撃ではあるものの、工夫することで使い勝手も広く、何より扱いやすいため、使えるようにしておいて損がない魔法である。
A9: 920_ | B9: Creates a wall of magical energy that bears the brunt of attacks. It deploys shields that protect against both physical and magical damage. Each of these shields has HP, and will disappear once it reaches zero. When used in Momentum mode, the tech's effect will be applied to all allies. Not only can this tech be used to protect the user, it can also grant protection to one's charge, and is often used by those who work as mercenaries and bodyguards. | C9: Tạo ra một lớp lá chắn ma thuật có thể chịu được nhiều đòn tấn công. Triệu hồi các khiên ma thuật có thể đỡ các đòn tấn côn pháp thuật và vật lí. Các khiên có HP riêng, khi hết sẽ lập tức biến mất. Khi sử dụng ở chế độ Momentum, hiệu ứng của chiêu thức đồng thời áp dụng lên đồng minh. Không chỉ bảo vệ người sử dụng, có thể chọn người khác để cùng bảo vệ, hợp với lính đánh thuê hoặc bảo vệ. | D9: 魔力の障壁により、ダメージを肩代わりしてくれる壁を作る。物理攻撃には物理盾が、魔法攻撃には魔法盾が受けてくれる。盾には、ともにHPが設定されており、0になると消滅する。刹那を発動すると、効果が味方全体に発生するようになる。 使用者を護るというのは当然として、護衛対象を護るのにも便利であり、傭兵稼業を生業とする者たちがよく使っている。
A10: 921_ | B10: Fires a blade of energy. This tech is useful for attacking from a distance, and can also pierce through multiple enemies in a straight line, although damage is reduced with each successive hit. When used in Momentum mode it will also recover the HP of all allies. When used effectively, this tech can therefore provide both powerful attack and defense simultaneously. | C10: Bắn ra 1 tia năng lượng. Chiêu thức phù hợp với lối tấn công tầm trung-xa, gây sát thương đa mục tiêu trên 1 đường thẳng, sát thương giảm dần sau mỗi lần trúng thành công kẻ địch. Khi sử dụng ở chế độ Momentum sẽ hồi phục HP cho toàn bộ đồng minh. Khi sử dụng hiệu quả có thể đồng thời vừa là chiêu thức tấn công, vừa là chiêu thức phòng thủ. | D10: 闘気で作られた刃を飛ばすことで攻撃する。敵との間合いを取るのに便利であり、さらに刃は敵を貫通する効果を持つ。貫通するたびに威力は下がってしまう欠点はあるが、直線上にいる敵に一気に攻撃できるのが優秀である。 刹那を発動すると、味方全体のHPを回復することができるため、上手く使えば、攻防一体の非常に扱いやすい魔法となる。
A11: 922_ | B11: The user uses magical energy to sense enemy movements, then seizes a momentary gap in their defense to move behind them in a split second and strike. Although the damage caused is not that great, when used in Momentum mode, this tech will also cause extremely powerful additional damage. It is said to have been created for use in assassinations, though this is uncertain. | C11: Người dùng sử dụng năng lượng pháp thuật thăm dò hành động kẻ địch, sau đó chọn 1 điểm mù của kẻ địch, di chuyển ra đó trong chớp mắt và đột kích. Dù sát thương không quá lớn, khi sử dụng ở chế độ Momentum, chiêu thức có thể gây thêm 1 lượng sát thương cực lớn. Dù không chắc chắn, chiêu thức này có thể được tạo ra vì class sát thủ. | D11: 敵から放たれる気配を魔力によって察知し、隙ができた一瞬に敵の背後に回り込んで斬りつける攻撃である。 威力自体は控えめではあるものの、刹那を発動すると、非常に威力の高い攻撃を追撃することができる。暗殺をするために作られたものと言われるが、本当かは定かではない。
A12: 923_ | B12: Attacks using a blast created by combining physical and magical energy. Damage is calculated according to the lower of the enemy's physical defense or magical defense, making this a very useful tech. When used in Momentum mode, multiple hits with a high critical hit rate will also be inflicted. This tech gets its name from its divine appearance, and boasts equally magnificent power. | C12: Tấn công bằng 1 vụ nổ tạo ra bằng việc kết hợp năng lượng vật lí và pháp thuật. Sát thương gây ra dựa trên chỉ số phòng ngự vật lí hoặc ma pháp của đối phương, khiến cho chiêu thức cực kì hữu dụng. Khi sử dụng ở chế độ Momentum có đi kèm liên kích và khả năng chí mạng cao. Chiêu thức lấy tên từ vẻ ngoài thần thánh của nó, đồng thời có sức sát thương cao. Đẹp mà chất. | D12: 闘気と魔力を練り合わせて作りあげた破壊の衝撃で攻撃する。敵の物理防御と魔法防御の低い方がダメージ算出に使われるため、使い勝手がいい。刹那システムを発動すると、クリティカル率が高い連続攻撃が発生する。 神々しい見た目から名づけられた魔法であるが、名前に負けていない威力を誇っている。
A13: 924_ | B13: This tech creates a magical energy source that emanates spiritual power. It casts Concentration on all allies, automatically recovering MP. When used in Momentum mode, its duration will be increased. Developed in order to enable continued combat during long missions, this is an extremely useful tech, and a very popular one. | C13: Chiêu thức tạo ra 1 nguồn pháp thuật tỏa ra sức mạnh linh hồn. Buff hiệu ứng Tập Trung đối với toàn bộ đồng minh, tự động hồi toàn bộ MP. Khi sử dụng ở chế độ Momentum sẽ giảm thời gian chờ. Để hỗ trợ các cuộc chiến, nhiệm vụ dài hơi, chiêu thức được phát triển và rất hữu dụng, phổ biến. | D13: 精神力が湧きでる魔力源を生み出す魔法である。集中状態となり、MPが自動で回復するようになる。刹那システムを発動すると、発生時間が長くなる。 長時間の任務遂行を可能とするために、継戦能力を高めるために作られたものである。扱いやすい魔法であり、利便性も極めて高いため、愛用する者が多い。
A14: 925_ | B14: Purifies the spirit, recovering knocked-out allies. It will also recover the HP of those who are not knocked out. When used in Momentum mode, it will cast Auto-Revive status on allies for a set period of time. Although a useful tech that can be employed in a variety of situations, it requires its user to possess plentiful magical energy reserves, and so is not often seen in use. | C14: Thanh lọc linh hồn, hồi sinh các đồng minh đã bị knock-out, đồng thời hồi phục HP cho những đồng minh còn lại. Khi sử dụng ở chế độ Momentum sẽ tự động buff hiệu ứng Auto-Revive (tự động hồi sinh) cho đồng minh trong 1 khoảng thời gian cố định. Dù là 1 kĩ nẵng hữu ích và có tác dụng trong rất nhiều thời điểm, nó tiêu tốn của người dùng rất lượng lớn MP, vì vậy Thường không bắt gặp | D14: 魂を浄化することで、戦闘不能者ですら復活させることができる。戦闘不能ではない者に対してもHP回復できるという特性がある。刹那システムを発動すると、自動復活がしばらくの間発生するため、有用性が高い。 いろんな状況に対応できる便利な魔法ではあるが、高い魔力資質を持つ者にしか使えないため、なかなかお目にかかれない魔法でもある。
A15: 926_ | B15: The user channels power into the sword, jumps up, and then swings down with their full weight behind the weapon, releasing all the channeled energy upon impact. When used in Momentum mode, it will also cause additional physical damage to all enemies. Although the principle behind this attack is simple, it takes a huge toll on the user's body, and so is not a tech that can be used by just anyone. | C15: Người dùng truyền năng lượng vào thanh kiếm, nhảy lên, dồn toàn bộ trọng lượng cơ thể vào thanh kiếm và vung xuống, giải phóng năng lượng trong thanh kiếm. Khi sử dụng ở chế độ Momentum sẽ gây thêm sát thương cho toàn bộ kẻ địch. Dù nguyên lí của chiêu thức rất đơn giản, cơ thể người dùng sẽ phải chịu áp lực rất lớn, vậy nên không phải ai cũng có thể dùng được chiêu thức này. | D15: 持てる闘気を剣に流し込み、ジャンプしてから全体重をかけて、剣を振りおろした瞬間に、闘気を一気に爆発させる攻撃である。刹那システムを発動すると、敵全体に物理攻撃が発生する。 やっていることはシンプルながら、身体にかかる負荷は大きく、使い手を選ぶ魔法であると言えよう。
A16: 927_ | B16: Awakens dormant power, instantly filling the SP gauge and increasing the rate at which it fills up for a set period. When wanting to make full use of Momentum mode during battle, this tech is ideal. When used in Momentum mode, its duration will be increased. Although an extremely useful tech for mercenaries who must overcome any adverse situation, it requires a high level of ability from its user, and so is not often seen in use. | C16: Thức tỉnh năng lượng tiềm ẩn, ngay lập tức hồi đầy SP và tăng tốc độ hồi SP trong 1 khoảng thời gian. Chiêu thức rất hữu dụng khi muốn sử dụng chế độ Momentum đạt hiệu quả cao nhất. Ở chế độ Momentum, thời gian sử dụng tăng lên. Mặc dù chiêu thức rất hữu dụng đối với lính đánh thuê khi chống lại kẻ địch, nó yêu cầu người dùng có năng lực cao, vì vậy không thường xuyên bắt gặp chiêu thức này. | D16: 人間の眠る力を引き出すことができる。SPが一気にたまり、さらにSPがしばらくの間はたまりやすくなる。刹那システムを使いたいときにはうってつけの魔法と言える。刹那システムを発動すると、発生時間が長くなる。 どんな状況であっても任務遂行を求められる傭兵にとって、便利なものではあるが、使用に高い能力が求められるのか、使い手はあまり見ない。
A17: 928_ | B17: Stimulates the magical energy inside the body, creating an attack that uses Momentum power to maximum efficiency. The SP accumulated when using this tech is higher than usual, and the damage inflicted also increases according to the user's SP. When used in Momentum mode it will also recover HP, and if used effectively, battles can easily be won using this tech alone. It is said to have been invented by a legendary mercenary during a sacrificial pilgrimage. | C17: Kích thích năng lượng pháp thuật trong cơ thể, tạo ra 1 vụ tấn công sử dụng năng lượng Momentum để đạt hiệu quả cao nhất. SP tích lũy khi sử dụng chiêu thức nàycao hơn bình thường. Khi sử dụng ở chế độ Momentum còn hồi phục HP, và nếu được sử dụng hiệu quả, chỉ riêng chiêu thức này có thể kết thúc cả trận đấu. Tác giả của chiêu thức được đồn đại là 1 lính đánh thuê huyền thoại, sáng tạo khi đi hành hương. | D17: 体内にある魔力を活性化して、刹那の力を最大限活用する攻撃を行う。攻撃したときにより多くSPがたまり、SPが高いほど威力が大きくなる。刹那システムを発動すると、HP回復もできるので、上手く使えば、この魔法だけでも戦い抜ける。 伝説の傭兵がいけにえの旅路の最中で生みだした攻撃と言われている。
... A223: 1134_ | B223: Triggering Momentum mode when being attacked while HP is below 20% will generate a counterattack with an available combo. This spritnite stone has existed since before the Momentum system was completed, and when first discovered, its purpose was unknown. After many years of research, its power can now be used. | C223: Triggering Momentum mode when being attacked while HP is below 20% will generate a counterattack with an available combo. This spritnite stone has existed since before the Momentum system was completed, and when first discovered, its purpose was unknown. After many years of research, its power can now be used. | D223: HPが20%以下のときに攻撃を受けて、刹那システムを発動すると、使用可能な連携で攻撃した敵に反撃することができる。 刹那システムが完成する前から存在していた法石であり、発見された当初は使い方がわからないものであったが、研究を続けた結果、使いこなせるまでに至っている。

Sheet BraveStoryGeographyMessage
A1: ID | B1: English | C1: Vietnamese | D1: Note
A2: 513.001_ | B2: 2 | D2: 2
A3: 514_ | B3: True | D3: True
A4: 514.001_ | B4: 0 | D4: 0
A5: 515_ | B5: 45 | D5: 45
A6: 516_ | B6: A picturesque harbor on the coast of Nive Island. The ferries that sail to and from it serve as the only route between Nive and the mainland, so it has been built to accommodate ships of any size. All the sacrifices depart from here when beginning their pilgrimages, and it is referred to by some local people as "Farewell Harbor." The sea breeze means that snow does not settle as readily as on other parts of the island, but on windy days, powdered snow can often be seen dancing in the air. | C6: Một cảng biển thơ mộng trên bờ biển đảo Nive. Là cảng biển duy nhất trên đảo, nó được xây dựng để phù hợp với thuyền ở mọi kích cỡ di chuyển từ đảo ra Lục địa và ngược lại. Mọi vật tế bắt đầu cuộc hành hương của mình ở đây, vì vậy cảng này còn có tên là "Cảng Biệt Ly". Gió biển nhè nhẹ, tuyết ở đây rơi cũng không dày như ở các khu khác của đảo. Nhưng vào ngày gió mạnh, nơi này cũng có thể xuất hiện tuyết rơi. | D6: モル島にある美しい港。 本島と行き来できる唯一の手段が船による航路だけなので、大型船も停泊できるように設計されている。 いけにえが旅立つときは必ずこの港からなので「別れの港」と呼ぶ者もいる。 潮風の影響でそれほど深く雪は積もらないが、風の強い日は粉雪が舞うことも多い。
A7: 516.001_
A8: 516.002_
A9: 516.003_
A10: 517_ | B10: The village from which all the sacrifices are sent forth. The sacrificial tradition began here, and so it is known across the land as the "village of sacrifice." The sacrifices, who protect everyone from the monsters, are the only hope of people everywhere, and so Nive carries a grave responsibility. The people of the village therefore have a strong sense of duty and pride. | C10: Ngôi làng của tất cả các vật tế. Phong tục hiến tế cũng từ đây mà sinh ra, vì vậy ngôi làng được cả thế giới gọi là "Làng Hiến Tế". Những vật tế, những người bảo vệ mọi người khỏi quái vật, là niềm hi vọng duy nhất của tất cả, vì vậy ngôi làng có trách nhiệm rất lớn. Cũng chính vì thế, người dân trong làng có tinh thần trách nhiệm cùng danh dự rất lớn. | D10: いけにえを送り出せる唯一無二の村。 モルとは古代語で「雪深い」という意味である。 いけにえの歴史はこの村から始まったもので、そのため「はじまりの村」と言えば、知らない者はいない。 人々を魔物から守れる存在であるいけにえは、かけがえのない希望であるため、それを送り出せるモルの責任は重く、村人たちは使命感と誇りに支えられて、生活を営んでいる。
A11: 517.001_
A12: 517.002_
A13: 517.003_
A14: 518_ | B14: A forest situated to the northeast of <NAME=MA_0003_01>. Anyone who visits the woods for the first time and sees the sunlight filtering through the boughs of the trees, and the stunning red of the deciduous tree leaves against the brilliant white snow, will instantly understand the reason for this name. | C14: Một khu rừng ở phía Đông Bắc của <NAME=CP_0003_01>. Lữ khách tới đây sẽ ngay lập tức hiểu về cái tên của nó. Mặt trời xuyên qua từng tán cây, màu lá nhuộm đỏ rực cả một vùng trời đối lập với màu tuyết trắng xóa... | D14: <NAME=MA_0003_01>の北東に位置している森。 ヨーデとは古代語で「美しい」という意味で、ここを初めて訪れた者は、木々のあいだから差しこむ木漏れ日や冬期でも色づいている落葉樹の紅い葉が雪の白さに映えていて、まさしくヨーデと名づけられた理由に納得するという。
A15: 518.001_
A16: 518.002_
A17: 518.003_
A18: 519_ | B18: A monument engraved with the names of all the past sacrifices. The souls of the sacrifices are thought to return as the snow that falls across the land, and this monument was built in honor of them. The cliff on which it stands is considered a holy ground by the people of Nive, and it is time-honored tradition that all women chosen as sacrifices offer up a prayer to the monument before departing on their journeys. | C18: Bia mộ có khắc tên của tất cả những vật tế. Linh hồn của các vật tế sẽ trở về mỗi khi tuyết đầu mùa rơi, và bia mộ này được xây để tưởng nhớ họ. Vách đá nơi đặt bia mộ là vùng đất thiêng của đảo Nive, và trước khi bắt đầu cuộc hành hương, mọi vật tế sẽ đến đây cầu nguyện. | D18: 歴代のいけにえたちの名前が刻まれている石碑。 名残雪とは、春になっても残っている雪という意味であり、この村から旅立ってなお、いけにえの魂は名残雪のように世界を優しく包んでいるという想いをこめて建てられた。 村人たちにとっては聖域とも言える場所である。 いけにえに選ばれた女性は一度はこの石碑に祈りを捧げることが古くからの習わしとなっている。
A19: 519.001_
A20: 519.002_
A21: 519.003_
A22: 520_ | B22: An inlet beach on the coast of the Floneian Territories. Although it is not immediately apparent, the tide here is fierce, and if one is careless, it is easy to be swept out to sea by its current. There were once plans to build a harbor here, but they were abandoned due to the aquatic monsters that frequent the beach's sands. As the years passed, the beach became forgotten, and its shore lies empty, save for the rocks. | C22: Một bờ vịnh trên lãnh thổ Floneian. Mặc dù không rõ ràng nhưng thủy triều nơi này rất mạnh, dòng biển có thể cuốn trôi người ta ra biển nếu bất cẩn. Đã từng có kế hoạch cho xây dựng cảng biển ở nơi này nhưng đã bị dừng lại bởi lũ quái vật thường xuyên hoạt động quanh đây. Rất nhiều năm trôi qua, vùng vịnh đã bị quên lãng. Chẳng còn gì ở đây ngoài cát, gió, biển, sỏi đá và quái vật. | D22: 湾状になっている浜辺。 海面からはわからないが複雑な潮の流れになっており、ヘタに海流に飲みこまれるとそのまま、外洋へと流されてしまう。 かつてはここに港を作る計画もあったが、頻繁に水棲の魔物が出没するため断念。時代とともに忘れ去られてしまった。 今はただ岩礁のみが残っている。
A23: 520.001_
A24: 520.002_
A25: 520.003_
A26: 521_ | B26: A town situated to the north of the Forgotten Shore. The view of the rising sun to be found here is the most unbroken of any on the mainland. It once thrived as a port town, but one year, when the sacrificial pilgrimage ended in failure, it was ravaged by monsters and left in ruins. It is said that figures can sometimes be seen wandering through the town, and it is possible that these are the lingering souls of its former inhabitants who refuse to leave. | C26: Một thị trấn nằm phía Bắc của Bờ Biển Bị Lãng Quên. Bình minh ở nơi này đẹp và trọn vẹn hơn so với bất cứ đâu trên Lục địa. Đã từng là một thị trấn cảng tấp nập, vì một lần lễ hiến tế thất bại, thị trấn đã bị tàn phá bởi quái vật và cuối cùng bị bỏ hoang. Vẫn có người nhìn thấy vài bóng hình đi quanh quẩn trong thị trấn. Có lẽ đó là linh hồn của những người gắn bó với thị trấn, quyến luyến không rời. | D26: 忘れられた浜辺の北に位置する村。 ゴザとは古代語で「朝日」という意味であり、本島で最も早く夜明けが見えるところからその名がついた。 かつては港町として繁栄したが、その年のいけにえの旅が失敗に終わり、増殖した魔物たちに滅ぼされ、廃墟となってしまった。 時折、うろついている人影を見かけるという。 いまだ死を受け入れられぬ村人たちが、魂となってさまよっているのかもしれない。
A27: 521.001_
A28: 521.002_
A29: 521.003_
A30: 522_ | B30: A small village situated near the mountains. Due to its mild climate, its soils provide relatively plentiful harvests. Because of its ample crops, it once served as a garrison for the knights of the ancient kingdom. The stalwart gates erected at that time can still be seen today, and a watchtower also remains in the center of the village. The village has no official leader, but <NAME=NPC_10050>, the captain of the local resistance, essentially fulfills this role. | C30: Một ngôi làng nhỏ nằm gần núi. Bởi vì khí hậu ôn hòa nên nơi đây trồng trọt rất khá. Bởi vì mùa màng bội thu, nơi đây từng là nơi đóng quân của đội kị sĩ vương quốc cổ đại. Đến bây giờ vẫn còn dấu tích của cổng doanh trại khi ấy, và một tháp canh gác ở trung tâm làng. Ở đây không có trưởng làng nhưng <NAME=NPC_10050>, thủ lĩnh dân làng, đang tạm thời đảm nhiệm chức vụ này. | D30: 山間に位置している小さな村。 気候が穏やかで比較的農作物が収穫しやすいため、古代語で「恵み」という意味をもつ、ユラルという名をつけられた。 その豊富な作物を理由に、いにしえの王国の騎士団が駐留するため駐屯地としての役割も持っていた。 そのため、今でも門の造りは頑丈で、村の中央には物見台が設置されている。村長という役職は置かれず、自警団の団長<NAME=NPC_10050>が実質、まとめ役である。
A31: 522.001_
A32: 522.002_
A33: 522.003_
A34: 523_ | B34: Settlements were once dotted around these plains, but no trace of them remains today. There are no landmarks to speak of, and when strong winds cause the snow to blow up into the air in thick clouds, it is easy to become stranded. | C34: Dân du mục thường sinh sống quanh những vùng đồng bằng này, nhưng đã không còn vết tích con người sinh sống ở đây ngày nay. Không có địa điểm nào nổi bật, và khi gió mạnh, tuyết rơi nhiều, khu vực này có nguy cơ bị cô lập. | D34: かつては複数の集落が点在していた場所だが、今は見る影もない。 目印もなく、ひとたび地吹雪が起こると、遭難の危険性がある。
A35: 523.001_
A36: 523.002_
A37: 523.003_
A38: 524_ | B38: A series of caves leading between <NAME=MA_0010_01> and <NAME=MA_0014_01>. The pillars of ice found in its caverns give off a luminous blue hue. Although perilous, these caves serve as the only route between Purikka and Floneia, and it is said that many travelers have lost their lives to the monsters that dwell within them. | C38: Một hệ thống hang động nằm giữa <NAME=MA_0010_01> và <NAME=MA_0014_01> Những tảng băng tìm thấy trong hang động mang sắc xanh rực rỡ. Mặc dù nguy hiểm, những cái hang này là con đường duy nhất đi từ Purikka đến Floneia, đã có rất nhiều khách lữ hành mất mạng vì những con quái vật sống trong này. | D38: <NAME=MA_0010_01>と、<NAME=MA_0014_01>の間にある洞窟。 カッチは古代語で「青」という意味があり、洞窟内部に点在する氷柱などが青白く光って見えることからこの名がついた。 ユラルとウカテイナを行き来するためには必ず通らなければならない難所で、ここに生息している魔物に襲われて命を落とす者も少なくないという。
A39: 524.001_
A40: 524.002_
...

Sheet BraveStoryMemoMessage
A1: ID | B1: English | C1: Vietnamese | D1: Note
A2: 1134.001_ | B2: 2 | D2: 2
A3: 1135_ | B3: True | D3: True
A4: 1135.001_ | B4: 0 | D4: 0
A5: 1136_ | B5: 36 | D5: 36
A6: 1137_ | B6: The Sacrifice | C6: Vật Hiến Tế | D6: いけにえ
A7: 1138_ | B7: A custom that has been carried out in Nive Village for many years. In order to appease the savage monsters, the chosen sacrifice travels to the Last Lands to perform the sacrificial rites. It is customary for females to be chosen, as they generally possess greater magical energy than males. Up until now these rites have been carried out once every ten years, but because the monsters are now increasing in number more rapidly, the time between pilgrimages has been shortened. | C7: Có 1 phong tục tồn tại ở làng Nive đã rất nhiều năm. Để khiến cho những con quái vật nguôi giận, vật tế được chọn phải đi tới vùng đất Tận Cùng để thực hiện nghi thức hi sinh. Thường thường, người được chọn là nữ giới, bởi họ có năng lượng pháp thuật cao hơn nam. Nghi lễ này diễn ra 10 năm 1 lần, nhưng vì càng ngày quái vật xuất hiện càng nhiều, thời gian giữa 2 lần tế lễ bị rút ngắn lại. | D7: モルの村が長年に渡り行ってきた慣習。 いけにえとなった者は荒ぶる魔物を鎮めるため、最果ての地へと赴きその身を捧げる。いけにえとして選ばれるのは魔力の観点から女性が通例となっている。 これまで十年に一度行われてきた儀式だが、昨今の魔物増加の影響により、その周期は短くなっている。
A8: 1139_ | B8: The Sacrifice's Protection | C8: Sự Bảo Vệ Của Vật Hiến Tế | D8: いけにえの守護
A9: 1140_ | B9: It is said that once the sacrifice fulfills her duty, the threat of the monsters will disappear, bringing peace to the mainland and the surrounding islands. The vast majority of people therefore regard the sacrifices with great esteem, and will do their best to aid them on their journeys. However, few people today know the reason why the sacrificial rites appease the monsters, and as a result, there are also those who doubt the effectiveness of the sacrifices. | C9: Sự hi sinh của 1 vật tế có thể đổi lấy 1 khoảng thời gian yên bình cho Lục địa cũng như các đảo lân cận. Hầu hết mọi người rất tôn sùng vật tế, và làm tất cả những gì để giúp vật tế trên chuyến hành trình của họ. Tuy nhiên, số người biết về nghi lễ này ngày một ít, cũng như tại sao lễ tế có thể làm ổn định lũ quái vật. Vì vậy, có cơ số người nghi ngờ tính hiệu quả của lễ tế này. | D9: いけにえがその役目を果たすことで、魔物の脅威は去り、本島やその周辺の島々の平穏は守られると伝えられている。そのため、ほとんどの人々はいけにえを尊重し、協力してくれる。 だが、なぜいけにえが魔物を鎮めることができるのか、その理由を知る者は今ではほとんどいない。その結果、いけにえの価値を認めない者も中には存在する。
A10: 1141_ | B10: The Pilgrimage's Route | C10: Hành Trình Hành Hương Của Vật Tế | D10: いけにえの旅路
A11: 1142_ | B11: The route and means of transport for the sacrificial pilgrimage is determined based on a variety of factors, such as weather conditions and environmental changes. In most cases, after departing from Nive Village, the sacrifice and her guard will first travel to the town of Floneia to gather information. From there, they will choose how to continue their journey - for example, by land, or by sea. | C11: Lộ trình và phương tiện di chuyển của vật tế trên đường tới Vùng đất Tận Cùng được quyết định dựa trên rất nhiều yếu tố, như là điều kiện thời tiết hay sự thay đổi môi trường. Hầu hết, sau khi khởi hành từ làng Nive, vật tế cùng những người bảo vệ cô sẽ đến Thị trấn Floneia để thu thập thông tin. Từ đó, họ sẽ chọn cách để tiếp tục cuộc hành trình - đi bằng đường biển, đường bộ,... | D11: その時の気象状況や環境変化などさまざまな要素を判断し、いけにえの交通手段や道順が決定されている。 モルの村を出発したいけにえは大抵の場合、本島の情報を得るためウカテイナの町に立ち寄り、進路を決定する。そこで陸路や海路など、その時々の状況に応じていくつかの旅路を選択して進んでいくのが常套手段となっている。
A12: 1143_ | B12: The Sacrifice's Guard | C12: Người Bảo Vệ Của Vật Tế | D12: 護衛隊
A13: 1144_ | B13: A special guard formed in order to see the sacrifice safely to the Last Lands. The guard is absolutely essential to the pilgrimage's success. It is not made up of a set number of people; its number is decided based on the ability of its members. However, the Last Lands are a perilous place, and can only be crossed by those who possess extremely high magical energy. As a result, no sacrifice's guard is ever thought to have reached the pilgrimage's final destination intact. | C13: 1 đội bảo vệ đặc biệt sẽ được cử đi bảo vệ vật tế cho tới khi cô đến Vùng đất Tận Cùng an toàn. Đội bảo vệ đóng vai trò quan trọng trong sự thành công của lễ tế. Đội không xác định số người, số người trong đội dựa trên năng lực của từng cá nhân. Tuy nhiên, Vùng đất Tận Cùng là 1 nơi nguy hiểm, chỉ những người có pháp lực cực cao mới có thể đi vào. Vì vậy, không người bảo vệ nào có thể đi cùng vật tế đến cuối cùng. | D13: いけにえを無事に最果ての地まで送り届けるために編成される特別な集団。 事実上、いけにえの旅を成功させるために欠かせない存在である。個人の能力が判断材料となるため、その人数は一定ではない。 ただ、護衛隊として真の終着点までたどり着けた者は過去に存在しない。これは、最果ての地が、高い魔力を持つ者でないと進むことすら適わない過酷な環境になっているためである。
A14: 1145_ | B14: Monsters | C14: Quái Vật | D14: 魔物
A15: 1146_ | B15: Beasts that feed on magical energy. Many monsters will often attack humans and their settlements, and they are feared and hated across the land. Their numbers and ferocity begin to increase every ten years or so, and if the sacrificial pilgrimage fails, their attacks on towns and villages will grow more intense. When this happens, they will sometimes destroy some villages completely. It is said that long ago monsters did not exist, but the validity of these claims is uncertain. | C15: Quái vật sống nhờ vào năng lượng ma pháp. Rất nhiều quái vật sẽ thường tấn công con người và thành trì của họ, vì vậy mọi người đều sợ và thù ghét quái vật. Số lượng và sự tàn ác của chúng tăng dần đều mỗi 10 năm, và nếu lễ tế thất bại, cuộc tấn công của chúng vào thành trì của con người sẽ càng thêm dữ dội. Khi điều này xảy ra, rất nhiều nơi sẽ bị phá hủy. Nghe nói trước đây, quái vật không hề tồn tại, nhưng chẳng có ai có thể khẳng định tính chính xác của nhận định này. | D15: 魔力を糧として生息している獣。 多くの魔物が人や集落を襲うため、人々からは恐れられ、忌み嫌われる存在である。 十年周期で数の増加や凶暴化が進むため、いけにえの旅が失敗した場合には、多くの町や村が襲われることになり、結果として滅ぼされた村もある。 太古の昔には存在していなかったという言い伝えもあるが、真相はいまだ不明である。
A16: 1147_ | B16: Magical Energy | C16: Năng Lượng Pháp Thuật (Pháp Lực) | D16: 魔力
A17: 1148_ | B17: An inert source of spiritual power that is said to flow within all living things. Magic, or "techs," are performed by releasing focused magical energy from the body. The power and properties of each being's magical energy vary greatly. However, the days when the majority of humans were able to make use of their magical energy have long passed, and today most have lost this ability. As a result, magic users are now extremely rare. | C17: Một lực lượng năng lượng tâm linh chảy trong tất cả vật sống. Pháp thuật, hay chiêu thức, được thực hiện bằng việc giải phóng pháp lực tích tụ trong cơ thể. Lượng pháp lực trong mỗi sinh vật rất khác nhau. Tuy nhiên, con người ngày nay hầu hết đã đánh mất khả năng sử dụng pháp thuật. Vì vậy số pháp sư còn lại là cực kì ít. | D17: 命あるもの全てに備わっているとされる、精神を具現化する根源的な力（具現化されたものが魔法となって体外へ放出される）。 その強さや性質は個体ごとに異なる。ただし、大部分の人間が魔力を持っていた時代は遙か彼方に消え去り、今ではほとんどの人間が魔力を失っている。そのため、現在では魔法を使える者は希少である。
... A77: 1208_ | B77: Monsters that have mutated due to the effects of spritnite. It is unknown exactly why such creatures came to be, but they seem to contradict the laws of nature. All spritnite-eaten monsters possess powerful abilities, and defeating them is said to be a very difficult task. | C77: Quái vật đột biến nhờ năng lực của đá spritnite. Không ai hiểu tại sao lại vậy, nhưng điều này dường như đi trái với quy luật của tự nhiên. Pháp thạch thực quái rất mạnh, rất khó để đánh bại. | D77: 法石の力に影響を受けて、変異してしまった魔物のことである。 どうして、そのような魔物が生まれるのかは謎ではあるが、自然の法則からは外れている存在のようではある。蝕まれた魔物たちは例外なく、際立った能力を持っており、倒すのが困難であると言われている。

Sheet BraveStoryMonsterMessage
A1: ID | B1: English | C1: Vietnamese | D1: Note
A2: 1208.001_ | B2: 2 | D2: 2
A3: 1209_ | B3: True | D3: True
A4: 1209.001_ | B4: 0 | D4: 0
A5: 1210_ | B5: 101 | D5: 101
A6: 1211_ | B6: Pengy | C6: Pengy | D6: ペンギィ
A7: 1212_ | B7: The most well-known of all monsters. It is found across the land, and there is also a high degree of intraspecific variation. Its wings have evolved to make them suited to delivering powerful "Slap" attacks, and in exchange have lost the ability of flight. Its large crest acts like a tail fin, stabilizing acceleration during its "Dive" attack. It can also use "Focus" to increase its own tension, boosting attack power, so be sure to defeat it before it does! Will drop a "Thawdrop" if defeated while afflicted with a status ailment. | C7: Loài quái vật được biết đến nhiều nhất. Chúng được tìm thấy ở khắp nơi và có lượng phân loài cực kì lớn. Cánh của chúng tiến hóa để phù hợp với đòn "Vả" của chúng, bù lại, chúng mất đi khả năng bay lượn. Bộ mào lớn đóng vai trò như một chiếc đuôi, giúp chúng giữ thăng bằng sau khi dùng chiêu "Lượn". Chúng còn có thể sử dụng "Tập Trung" để tăng độ căng thẳng của bản thân, dẫn đến việc tăng sức mạnh tấn công. Hãy tiêu diệt nó trước khi đó nhé! Có thể rớt ra "Tuyết Tan" nếu bị tiêu diệt khi đang bị ảnh hưởng bởi trạng thái tiêu cực. | D7: この世界で最もよく見かける、代表的な魔物。場所を問わず至る所に分布し、また種族内のバリエーションも非常に多い。 羽根は高威力の「ビンタ」に適した骨格に進化したため、その代償に飛行能力は失われた。 大きなトサカは「ダイブ」の加速を安定させるための垂直尾翼の役割を持つ。 自らのストレスを「ためる」ことで攻撃力を上昇するので、その前に倒そう！ 状態異常の最中に倒すと「雪解けドロップ」を落とす。
A8: 1213_ | B8: Hoppy | C8: Hoppy | D8: イワトビィ
A9: 1214_ | B9: A more powerful relative of the Pengy. It is mainly found in rocky areas, and gets its name from the hopping motion it makes when moving. Its crest is even larger than that of the Pengy, and as well as acting as a tail fin, also serves as an antenna for communication with other Hoppies. Hoppies use this ability to perform a synchronized "Rocket Rush" attack in pairs, and caution is thus advised when encountering more than one of the creatures. Will drop a "Round Stone" if defeated with Over Kill. | C9: Họ hàng của Pengy, mà mạnh hơn. Chúng thường được tìm thấy ở những vùng sỏi đá, và cái tên của chúng đến từ việc chúng nhảy để di chuyển. Bộ mào của chúng còn lớn hơn của Pengy, không chỉ là chiếc vây đuôi, chúng còn là chiếc ăng ten để các Hoppy giao tiếp với nhau. Các Hoppy sử dụng khả năng này để thực hiện đòn "Tên Lửa Vụt Bay" theo cặp, vì vậy cần phải cẩn thận khi đối đầu với nhiều Hoppy. Sẽ rớt ra "Đá Tròn" nếu bị tiêu diệt trong trạng thái Bá Đạo | D9: ペンギィの上位種。主に岩場に生息し、ピョンピョン飛び跳ねる動きをすることからこう呼ばれるようになった。 ペンギィよりもさらに大型化したトサカは、垂直尾翼としての機能に加えて、イワトビィ同士で意思疎通を行うためのアンテナとしての機能を併せ持つ。 その能力により、２体のイワトビィでタイミングを合わせて放つ「ロケットラッシュ」にはくれぐれも気をつけよう。 オーバーキルで倒すと「まるい石」を落とす。
A10: 1215_ | B10: Empy | C10: Empy | D10: コウティ
A11: 1216_ | B11: The most powerful member of the Pengy species. Although its genetic makeup differs from that of the Pengy by a mere 0.01%, its appearance is strikingly different. Its crown-like crest has evolved into a more powerful antenna than that of the Hoppy, and it is even able to control other Empies remotely. This ability is used to unleash an extremely powerful "Rocket Rush" attack in which three Empies move in perfect synchronization. Will sometimes drop an "Emperor's Crown Gem." | C11: Phân loài mạnh nhất của Pengy. Mặc dù gen của chúng và Pengy chỉ khác nhau chưa đến 0.01%, ngoại hình của chúng lại khác nhau hoàn toàn. Lông mao hình vương miện tiến hóa trở thành chiếc ăng ten còn mạnh hơn của Hoppy, thậm chí còn có thể điều khiển các Empy từ xa. Khả năng này giúp Empy thực hiện đòn "Tên Lửa Vụt Bay" với 3 Empy cùng sự đồng điệu hoàn hảo. Thỉnh thoảng sẽ rớt ra "Ngọc Thạch Ngai Vàng Của Hoàng Đế". | D11: ペンギィの最上位種。ペンギィとはわずか0.01％しか遺伝子構造に差がないのにも関わらず、その外見はまったくと言って良いほど異なる。 王冠のような形状をしたトサカは、イワトビィのものよりもさらに高精度のアンテナと化しており、他のコウティをリモート操作することさえ可能。 その能力により、コウティ３体の動きを完全にシンクロさせて放つ「ロケットラッシュ」は超強力！ 時々「王冠石」が手に入ることがある。
A12: 1217_ | B12: Scarly | C12: Scarly | D12: ベスィ
A13: 1218_ | B13: This unfortunate Pengy has been afflicted by a disease of unknown cause. Its body fluids have solidified and formed a stone inside its body, causing intense pain and fever. As a result, its eyes are constantly teary from pain, and its skin red from fever. When the creature is defeated, the stone inside it will occasionally remain intact. This stone, which bears a speckled pattern and emits a characteristic glow, is a highly valuable item known as the "Madara Spritnite." | C13: Loài Pengy tội nghiệp này đã bị lây nhiễm một căn bệnh kì quái. Chất lỏng trong cơ thể chúng dần dần đông cứng lại tạo thành đá, gây ra những trận đau và sốt dữ dội. Mắt chúng nhòa lệ vì đau, da chúng đỏ ửng lên vì sốt. Khi chúng bị tiêu diệt, những viên đá thỉnh thoảng sẽ còn ở lại. Những viên đá này, với những vệt lốm đốm và ánh sáng đặc trưng, là một trong những vật phẩm có giá trị cao, Pháp Thạch Madara. | D13: 魔物なのに原因不明の病魔に冒されてしまった可哀そうなペンギィ。体内の分泌物が固まって石を形成し、それにより疼痛・発熱などの症状を伴っている。疼痛のせいで瞳はいつも涙目、また発熱のせいで表皮も赤く染まっている。 倒すと、まれにその石がそのまま残ることがあり、その石は綺麗な斑模様、そして独特の輝きを放つ法石「マダラ法石」として珍重される。
A14: 1219_ | B14: King Pengy | C14: Pengy Vua | D14: スーパーペンギィ
A15: 1220_ | B15: A form of mutated Pengy. Although far larger in stature than a regular Pengy, the creature itself appears to be entirely unaware of this fact. It can be found mingling and living with Pengy colonies, seemingly under the impression that it is no different from the others. In combat it utilizes a diverse range of attacks, using "Royal Bite" with its giant beak, firing "Pengy Missiles" in all directions, and using "Power Dives" to rock the earth with its full body weight. | C15: Một loài Pengy đột biến. Mặc dù kích thước của chúng lớn hơn Pengy thông thường, loài sinh vật này có vẻ như hoàn toàn không biết điều ấy. Chúng thường sống cùng với Pengy thông thường, có lẽ vì trong mắt chúng, chúng không khác gì các Pengy. Chúng sử dụng rất nhiều đòn chiến đấu, sử dụng "Đớp" với cái mỏ của mình, bắn "Đạn Pengy" tứ tung, làm rung chuyển mặt đất với toàn bộ trọng lượng cơ thể mình bằng "Lượn Sức Mạnh". | D15: ペンギィが突然変異した魔物。ペンギィに比べてはるかに大きな体躯を持つものの、自身ではその自覚はまるで無し。自分をごくごく普通のペンギィと信じて疑わず、ペンギィの群れに紛れ込んで生活を共にする。 巨大な口を大きく開き敵を「かじりつくす」、自身のまわりにまんべんなく「ペンギィミサイル」発射、全体重を乗せて大地を揺るがす「パワーダイブ」などの多彩な攻撃を繰り出す。
A16: 1221_ | B16: King Hoppy | C16: Hoppy Vua | D16: スーパーイワトビィ
A17: 1222_ | B17: An unidentified monster that suddenly appeared in a Hoppy colony on the ice floes of the Floeberg Waters. It is an extremely rare monster, and only one specimen has so far been spotted. Although it usually lives peacefully together with the other Hoppies, when it detects the presence of humans it uses "Hoppy Fusion" to intake the other creatures like sacrifices, drastically increasing its own power. As such, it is a fearsome threat to both humans and monsters alike. | C17: Một loài quái vật chưa được nhận dạng, đột ngột xuất hiện lẫn vào các Hoppy trên những tảng băng trôi dạt tại Floeberg Waters. Là loài quái vật cực kì hiếm, chỉ có 1 cá thể duy nhất từng được phát hiện. Mặc dù chung sống hòa bình cùng các Hoppy, khi cảm nhận được sự tồn tại của con người, chúng sẽ ăn thịt đồng loại để gia tăng sức mạnh. Chúng đe dọa tới cả sự tồn tại của quái vật cũng như con người. | D17: イワトビィの群れの中に突如として現れた正体不明の魔物。他のイワトビィと共にロラの海の流氷の上で暮らしており、未だこの一匹以外は発見されていない希少な魔物。 普段は他のイワトビィと仲良く暮らしているものの、人間の気配を察知すると他のイワトビィを「イワトビィ合体」によりいけにえのように取り込んで大幅にパワーアップする。他のイワトビィにとってもある意味で恐ろしい魔物である。
... A207: 1412_ | B207: A Hoot-Hoot that has been eaten away at by spritnite, enhancing its motor nerves and reflexes to their utmost limits. This enables it to fly away at light-speed when spotted by humans, allowing it to disappear from sight each and every time. Will sometimes drop a "Crystallized Teardrop." | C207: A Hoot-Hoot that has been eaten away at by spritnite, enhancing its motor nerves and reflexes to their utmost limits. This enables it to fly away at light-speed when spotted by humans, allowing it to disappear from sight each and every time. Will sometimes drop a "Crystallized Teardrop." | D207: 法石に蝕まれたことで、運動神経・反射神経が極限まで研ぎ澄まされたハクホウ。 その異常なまでの運動神経・反射神経により、人間に気付くと超光速で飛び去り、確実に人間の前から姿を消す能力を獲得した。 時々「結晶化した涙」を落とすことがある。

Sheet BraveStoryNoteMessage
A1: ID | B1: English | C1: Vietnamese | D1: Note
A2: 1412.001_ | B2: 2 | D2: 2
A3: 1413_ | B3: True | D3: True
A4: 1413.001_ | B4: 0 | D4: 0
A5: 1414_ | B5: 14 | D5: 14
A6: 1415_ | B6: The Masked Mercenaries | C6: Lính Đánh Thuê Và Mặt Nạ | D6: 異端の傭兵たち
A7: 1416_ | B7: <NAME=CP_0001> receives a mission to rescue a girl who has been kidnapped by monsters. He joins up with fellow mercenary <NAME=NPC_10020> in order to carry out this mission. <NAME=CP_0001> and <NAME=NPC_10020> successfully defeat the monsters and rescue the girl. After <NAME=NPC_10020> leaves to take the girl back to her parents, a mysterious man appears before <NAME=CP_0001> with a new mission for him: the assassination of a young girl. | C7: <NAME=CP_0001> | D7: 魔物にさらわれた少女の救出。 という依頼を受けた<NAME=CP_0001>は、 傭兵の<NAME=NPC_10020>と合流し、任務を遂行する。 首尾よく魔物たちを倒し、 少女を解放する<NAME=CP_0001>と<NAME=NPC_10020>。 少女を親元に帰すために<NAME=NPC_10020>が 去っていったあと、謎の人物が<NAME=CP_0001>の前に現れ、 新たな依頼を提示する。 それはとある小さな村にいるひとりの少女を、 暗殺してほしいという依頼だった。
A8: 1416.001_
A9: 1416.002_
A10: 1416.003_
A11: 1417_ | B11: The Journey Begins | C11: Hành Trình Bắt Đầu | D11: はじまりの旅路
A12: 1418_ | B12: Arriving in <NAME=MA_0003_01>, <NAME=CP_0001> finds his target, <NAME=CP_0002>, who turns out to be the latest girl to be chosen as sacrifice. However, her guard, <NAME=CP_0003>, appears, and <NAME=CP_0001> is captured. Even though he tried to take her life, <NAME=CP_0002> sticks up for <NAME=CP_0001>. He is intrigued by her, and abandoning his mission for the moment, he agrees to join her guard. The party set sail on a ferry to the mainland, but the ferry is attacked by a giant monster, and sinks. | C12: Đến <NAME=MA_0003_01>, <NAME=CP_0001> tìm thấy mục tiêu của mình, <NAME=CP_0002>, người vừa được chọn làm vật hiến tế tiếp theo. Tuy nhiên, cận vệ của cô, <NAME=CP_0003>, xuất hiện và <NAME=CP_0001> bị bắt giữ. Dù anh từng có ý định lấy mạng cô, <NAME=CP_0002> vẫn đứng ra bảo vệ <NAME=CP_0001>. Cảm kích trước tấm lòng của cô, anh tạm gác nhiệm vụ và đồng ý gia nhập đội cận vệ. Cả nhóm lên tàu sang lục địa, nhưng con tàu bị quái vật khổng lồ tấn công và chìm xuống biển. | D12: <NAME=MA_0003_01>にやってきた<NAME=CP_0001>は、 標的である少女<NAME=CP_0002>と出会う。 彼女こそは今年のいけにえだった。 だが、そこに駆けつけた護衛隊の<NAME=CP_0003>らによって <NAME=CP_0001>は取り押さえられる。 命を狙われながらも<NAME=CP_0001>をかばう<NAME=CP_0002>。 彼女に興味を持った<NAME=CP_0001>は、 暗殺をいったん思いとどまり、護衛隊に参加する。 しかし、一行を乗せた船は巨大な魔物の襲撃を受けて、 沈められてしまう。
A13: 1418.001_
A14: 1418.002_
A15: 1418.003_
A16: 1419_ | B16: The Lone Swordsman | C16: Kiếm Sĩ Đơn Độc | D16: 許されざる孤剣
